<?xml version="1.0" ?>
<!-- =================================================================================== -->
<!-- |    This document was autogenerated by xacro from AJM2_1.xacro                   | -->
<!-- |    EDITING THIS FILE BY HAND IS NOT RECOMMENDED                                 | -->
<!-- =================================================================================== -->
<robot name="mrs" xmlns:xacro="http://www.ros.org/wiki/xacro">
  <!-- Constants for robot -->
  <!-- Import all Gazebo-customization elements, including Gazebo colors -->
  <material name="Blue">
    <color rgba="0.0 0.0 0.8 1.0"/>
  </material>
  <material name="Grey">
    <color rgba="0.7 0.7 0.7 1.0"/>
  </material>
  <material name="Grey2">
    <color rgba="0.9 0.9 0.9 1.0"/>
  </material>
  <material name="Red">
    <color rgba="0.8 0.0 0.0 1.0"/>
  </material>
  <material name="White">
    <color rgba="1.0 1.0 1.0 1.0"/>
  </material>
  <material name="Black">
    <color rgba="0.1 0.1 0.1 1.0"/>
  </material>
  <material name="LightGrey">
    <color rgba="0.6 0.6 0.6 1.0"/>
  </material>
  <material name="Orange">
    <color rgba="1.0 0.4 0.0 1.0"/>
  </material>
  <material name="DarkGrey">
    <color rgba="0.3 0.3 0.3 1.0"/>
  </material>
  <material name="Green">
    <color rgba="0.0 1.0 0.0 1.0"/>
  </material>
  <material name="Caster">
    <texture filename="package://pr2_description/materials/textures/pr2_caster_texture.png"/>
  </material>
  <material name="Wheel_l">
    <texture filename="package://pr2_description/materials/textures/pr2_wheel_left.png"/>
  </material>
  <material name="Wheel_r">
    <texture filename="package://pr2_description/materials/textures/pr2_wheel_right.png"/>
  </material>
  <material name="RollLinks">
    <texture filename="package://pr2_description/materials/textures/pr2_wheel_left.png"/>
  </material>
  <!-- materials for visualization -->
  <!--
  <xacro:include filename="$(find mrs_description)/urdf/materials.urdf.xacro" />
-->
  <!-- For 2 JM 2 PC 2 WM mobile robot -->
  <link name="base_footprint">
    <visual>
      <origin rpy="0 0 0" xyz="0 0 0"/>
      <geometry>
        <box size="0.001 0.001 0.001"/>
      </geometry>
      <material name="Red"/>
    </visual>
    <collision>
      <geometry>
        <box size="0.001 0.001 0.001"/>
      </geometry>
    </collision>
  </link>
  <joint name="base_footprint_joint" type="fixed">
    <origin rpy="0 0 0" xyz="0 0 0"/>
    <child link="base_footprint_dummy"/>
    <parent link="base_footprint"/>
  </joint>
  <link name="base_footprint_dummy"/>
  <link name="mrs_sm_wheel_link_1">
    <visual>
      <geometry>
        <cylinder length="0.1" radius="0.25"/>
      </geometry>
      <material name="Black">
        </material>
    </visual>
    <collision>
      <geometry>
        <cylinder length="0.1" radius="0.25"/>
      </geometry>
    </collision>
    <inertial>
      <mass value="1"/>
      <inertia ixx="1" ixy="0.0" ixz="0.0" iyy="1" iyz="0.0" izz="1"/>
    </inertial>
  </link>
  <joint name="mrs_sm_wheel_joint_1" type="fixed">
    <parent link="base_footprint"/>
    <child link="mrs_sm_wheel_link_1"/>
    <origin rpy=" 0 0.0 0" xyz="0.0 0 0"/>
  </joint>
  <gazebo reference="mrs_sm_wheel_link_1">
    <material>Gazebo/White</material>
    <selfCollide>false</selfCollide>
  </gazebo>
  <link name="1_jm_link_1">
    <visual>
      <geometry>
        <box size="0.1 0.4 0.3"/>
      </geometry>
      <material name="Grey2">
        </material>
    </visual>
    <collision>
      <geometry>
        <box size="0.1 0.4 0.3"/>
      </geometry>
    </collision>
    <inertial>
      <mass value="1"/>
      <inertia ixx="1" ixy="0.0" ixz="0.0" iyy="1" iyz="0.0" izz="1"/>
    </inertial>
  </link>
  <joint name="1_jm_joint_1" type="continuous">
    <parent link="mrs_sm_wheel_link_1"/>
    <child link="1_jm_link_1"/>
    <axis xyz="1 0 0"/>
    <origin rpy="0 -1.57079632679 0" xyz="0.0 0 0.1"/>
  </joint>
  <gazebo reference="1_jm_link_1">
    <material>Gazebo/Grey</material>
    <selfCollide>false</selfCollide>
  </gazebo>
  <link name="1_jm_link2_1">
    <visual>
      <geometry>
        <sphere radius="0.2"/>
      </geometry>
      <material name="Grey2">
          </material>
    </visual>
    <collision>
      <geometry>
        <sphere radius="0.2"/>
      </geometry>
    </collision>
    <inertial>
      <mass value="1"/>
      <inertia ixx="1" ixy="0.0" ixz="0.0" iyy="1" iyz="0.0" izz="1"/>
    </inertial>
  </link>
  <joint name="1_jm_joint2_1" type="revolute">
    <parent link="1_jm_link_1"/>
    <child link="1_jm_link2_1"/>
    <origin rpy="0 0 0" xyz="0.25 0 0"/>
    <axis xyz="0 0 1"/>
    <limit effort="100" lower="-1.57079632679" upper="1.57079632679" velocity="100"/>
  </joint>
  <gazebo reference="1_jm_link2_1">
    <material>Gazebo/Grey</material>
    <selfCollide>false</selfCollide>
  </gazebo>
  <link name="1_jm_link_2">
    <visual>
      <geometry>
        <box size="0.1 0.4 0.3"/>
      </geometry>
      <material name="Grey2">
        </material>
    </visual>
    <collision>
      <geometry>
        <box size="0.1 0.4 0.3"/>
      </geometry>
    </collision>
    <inertial>
      <mass value="1"/>
      <inertia ixx="1" ixy="0.0" ixz="0.0" iyy="1" iyz="0.0" izz="1"/>
    </inertial>
  </link>
  <joint name="1_jm_joint_2" type="continuous">
    <parent link="1_jm_link2_1"/>
    <child link="1_jm_link_2"/>
    <axis xyz="1 0 0"/>
    <origin rpy="0 -0.0 0" xyz="0.25 0 0"/>
  </joint>
  <gazebo reference="1_jm_link_2">
    <material>Gazebo/Grey</material>
    <selfCollide>false</selfCollide>
  </gazebo>
  <transmission name="1_jm_joint_1tran">
    <type>transmission_interface/SimpleTransmission</type>
    <joint name="1_jm_joint_1"/>
    <actuator name="1_jm_joint_1_motor">
      <hardwareInterface>EffortJointInterface</hardwareInterface>
      <mechanicalReduction>1</mechanicalReduction>
    </actuator>
  </transmission>
  <transmission name="1_jm_joint_2tran">
    <type>transmission_interface/SimpleTransmission</type>
    <joint name="1_jm_joint_2"/>
    <actuator name="1_jm_joint_2_motor">
      <hardwareInterface>EffortJointInterface</hardwareInterface>
      <mechanicalReduction>1</mechanicalReduction>
    </actuator>
  </transmission>
  <transmission name="1_jm_joint2_1tran">
    <type>transmission_interface/SimpleTransmission</type>
    <joint name="1_jm_joint2_1"/>
    <actuator name="1_jm_joint2_1_motor">
      <hardwareInterface>EffortJointInterface</hardwareInterface>
      <mechanicalReduction>1</mechanicalReduction>
    </actuator>
  </transmission>
  <link name="mrs_pcm_link_1">
    <visual>
      <geometry>
        <box size="0.35 0.35 0.35"/>
      </geometry>
      <material name="Blue">
          </material>
    </visual>
    <collision>
      <geometry>
        <box size="0.35 0.35 0.35"/>
      </geometry>
    </collision>
    <inertial>
      <mass value="0.01"/>
      <inertia ixx="1" ixy="0.0" ixz="0.0" iyy="1" iyz="0.0" izz="1"/>
    </inertial>
  </link>
  <joint name="mrs_pcm_joint_1" type="fixed">
    <parent link="1_jm_link_2"/>
    <child link="mrs_pcm_link_1"/>
    <origin rpy="0 -0.0 0" xyz="0.18 0 0"/>
  </joint>
  <gazebo reference="mrs_pcm_link_1">
    <material>Gazebo/Blue</material>
    <selfCollide>false</selfCollide>
  </gazebo>
  <link name="mrs_pcm_link_2">
    <visual>
      <geometry>
        <box size="0.35 0.35 0.35"/>
      </geometry>
      <material name="Blue">
          </material>
    </visual>
    <collision>
      <geometry>
        <box size="0.35 0.35 0.35"/>
      </geometry>
    </collision>
    <inertial>
      <mass value="0.01"/>
      <inertia ixx="1" ixy="0.0" ixz="0.0" iyy="1" iyz="0.0" izz="1"/>
    </inertial>
  </link>
  <joint name="mrs_pcm_joint_2" type="fixed">
    <parent link="mrs_pcm_link_1"/>
    <child link="mrs_pcm_link_2"/>
    <origin rpy="0 -0.0 0" xyz="0.35 0 0"/>
  </joint>
  <gazebo reference="mrs_pcm_link_2">
    <material>Gazebo/Blue</material>
    <selfCollide>false</selfCollide>
  </gazebo>
  <link name="2_jm_link_1">
    <visual>
      <geometry>
        <box size="0.1 0.4 0.3"/>
      </geometry>
      <material name="Grey2">
        </material>
    </visual>
    <collision>
      <geometry>
        <box size="0.1 0.4 0.3"/>
      </geometry>
    </collision>
    <inertial>
      <mass value="1"/>
      <inertia ixx="1" ixy="0.0" ixz="0.0" iyy="1" iyz="0.0" izz="1"/>
    </inertial>
  </link>
  <joint name="2_jm_joint_1" type="continuous">
    <parent link="mrs_pcm_link_2"/>
    <child link="2_jm_link_1"/>
    <axis xyz="1 0 0"/>
    <origin rpy="0 -0.0 0" xyz="0.25 0 0"/>
  </joint>
  <gazebo reference="2_jm_link_1">
    <material>Gazebo/Grey</material>
    <selfCollide>false</selfCollide>
  </gazebo>
  <link name="2_jm_link2_1">
    <visual>
      <geometry>
        <sphere radius="0.2"/>
      </geometry>
      <material name="Grey2">
          </material>
    </visual>
    <collision>
      <geometry>
        <sphere radius="0.2"/>
      </geometry>
    </collision>
    <inertial>
      <mass value="1"/>
      <inertia ixx="1" ixy="0.0" ixz="0.0" iyy="1" iyz="0.0" izz="1"/>
    </inertial>
  </link>
  <joint name="2_jm_joint2_1" type="revolute">
    <parent link="2_jm_link_1"/>
    <child link="2_jm_link2_1"/>
    <origin rpy="0 0 0" xyz="0.25 0 0"/>
    <axis xyz="0 0 1"/>
    <limit effort="100" lower="-1.57079632679" upper="1.57079632679" velocity="100"/>
  </joint>
  <gazebo reference="2_jm_link2_1">
    <material>Gazebo/Grey</material>
    <selfCollide>false</selfCollide>
  </gazebo>
  <link name="2_jm_link_2">
    <visual>
      <geometry>
        <box size="0.1 0.4 0.3"/>
      </geometry>
      <material name="Grey2">
        </material>
    </visual>
    <collision>
      <geometry>
        <box size="0.1 0.4 0.3"/>
      </geometry>
    </collision>
    <inertial>
      <mass value="1"/>
      <inertia ixx="1" ixy="0.0" ixz="0.0" iyy="1" iyz="0.0" izz="1"/>
    </inertial>
  </link>
  <joint name="2_jm_joint_2" type="continuous">
    <parent link="2_jm_link2_1"/>
    <child link="2_jm_link_2"/>
    <axis xyz="1 0 0"/>
    <origin rpy="0 -0.0 0" xyz="0.25 0 0"/>
  </joint>
  <gazebo reference="2_jm_link_2">
    <material>Gazebo/Grey</material>
    <selfCollide>false</selfCollide>
  </gazebo>
  <transmission name="2_jm_joint_1tran">
    <type>transmission_interface/SimpleTransmission</type>
    <joint name="2_jm_joint_1"/>
    <actuator name="2_jm_joint_1_motor">
      <hardwareInterface>EffortJointInterface</hardwareInterface>
      <mechanicalReduction>1</mechanicalReduction>
    </actuator>
  </transmission>
  <transmission name="2_jm_joint_2tran">
    <type>transmission_interface/SimpleTransmission</type>
    <joint name="2_jm_joint_2"/>
    <actuator name="2_jm_joint_2_motor">
      <hardwareInterface>EffortJointInterface</hardwareInterface>
      <mechanicalReduction>1</mechanicalReduction>
    </actuator>
  </transmission>
  <transmission name="2_jm_joint2_1tran">
    <type>transmission_interface/SimpleTransmission</type>
    <joint name="2_jm_joint2_1"/>
    <actuator name="2_jm_joint2_1_motor">
      <hardwareInterface>EffortJointInterface</hardwareInterface>
      <mechanicalReduction>1</mechanicalReduction>
    </actuator>
  </transmission>
  <link name="mrs_sm_wheel_link_2">
    <visual>
      <geometry>
        <cylinder length="0.1" radius="0.25"/>
      </geometry>
      <material name="Black">
        </material>
    </visual>
    <collision>
      <geometry>
        <cylinder length="0.1" radius="0.25"/>
      </geometry>
    </collision>
    <inertial>
      <mass value="1"/>
      <inertia ixx="1" ixy="0.0" ixz="0.0" iyy="1" iyz="0.0" izz="1"/>
    </inertial>
  </link>
  <joint name="mrs_sm_wheel_joint_2" type="fixed">
    <parent link="2_jm_link_2"/>
    <child link="mrs_sm_wheel_link_2"/>
    <origin rpy=" 0 1.57079632679 0" xyz="0.1 0 0"/>
  </joint>
  <gazebo reference="mrs_sm_wheel_link_2">
    <material>Gazebo/White</material>
    <selfCollide>false</selfCollide>
  </gazebo>
  <gazebo>
    <plugin filename="libgazebo_ros_control.so" name="gazebo_ros_control">
      <robotNamespace>/mrs</robotNamespace>
    </plugin>
  </gazebo>
</robot>
