<?xml version="1.0" ?>
<!-- =================================================================================== -->
<!-- |    This document was autogenerated by xacro from 2W1JM.xacro                    | -->
<!-- |    EDITING THIS FILE BY HAND IS NOT RECOMMENDED                                 | -->
<!-- =================================================================================== -->
<robot name="mrs" xmlns:xacro="http://www.ros.org/wiki/xacro">
  <!-- Constants for robot -->
  <!-- Import all Gazebo-customization elements, including Gazebo colors -->
  <material name="Blue">
    <color rgba="0.0 0.0 0.8 1.0"/>
  </material>
  <material name="Grey">
    <color rgba="0.7 0.7 0.7 1.0"/>
  </material>
  <material name="Grey2">
    <color rgba="0.9 0.9 0.9 1.0"/>
  </material>
  <material name="Red">
    <color rgba="0.8 0.0 0.0 1.0"/>
  </material>
  <material name="White">
    <color rgba="1.0 1.0 1.0 1.0"/>
  </material>
  <material name="Black">
    <color rgba="0.1 0.1 0.1 1.0"/>
  </material>
  <material name="LightGrey">
    <color rgba="0.6 0.6 0.6 1.0"/>
  </material>
  <material name="Orange">
    <color rgba="1.0 0.4 0.0 1.0"/>
  </material>
  <material name="DarkGrey">
    <color rgba="0.3 0.3 0.3 1.0"/>
  </material>
  <material name="Green">
    <color rgba="0.0 1.0 0.0 1.0"/>
  </material>
  <material name="Caster">
    <texture filename="package://pr2_description/materials/textures/pr2_caster_texture.png"/>
  </material>
  <material name="Wheel_l">
    <texture filename="package://pr2_description/materials/textures/pr2_wheel_left.png"/>
  </material>
  <material name="Wheel_r">
    <texture filename="package://pr2_description/materials/textures/pr2_wheel_right.png"/>
  </material>
  <material name="RollLinks">
    <texture filename="package://pr2_description/materials/textures/pr2_wheel_left.png"/>
  </material>
  <!-- materials for visualization -->
  <!--
  <xacro:include filename="$(find mrs_description)/urdf/materials.urdf.xacro" />
-->
  <!-- For 1 Jm mobile robot -->
  <link name="base_footprint">
    <inertial>
      <mass value="0.1"/>
      <origin rpy="0 0 0" xyz="0 0 0"/>
      <inertia ixx="1.0" ixy="0.0" ixz="0.0" iyy="1.0" iyz="0.0" izz="1.0"/>
    </inertial>
    <visual>
      <origin rpy="0 0 0" xyz="0 0 0"/>
      <geometry>
        <box size="0.001 0.001 0.001"/>
      </geometry>
      <material name="Red"/>
    </visual>
    <collision>
      <geometry>
        <box size="0.001 0.001 0.001"/>
      </geometry>
    </collision>
  </link>
  <joint name="base_footprint_joint" type="fixed">
    <origin rpy="0 0 0" xyz="0 0 0"/>
    <child link="base_footprint_dummy"/>
    <parent link="base_footprint"/>
  </joint>
  <link name="base_footprint_dummy"/>
  <link name="1_pcm_link_1">
    <visual>
      <geometry>
        <box size="0.3 0.3 0.3"/>
      </geometry>
      <material name="Blue">
          </material>
    </visual>
    <collision>
      <geometry>
        <box size="0.3 0.3 0.3"/>
      </geometry>
    </collision>
    <inertial>
      <mass value="0.01"/>
      <inertia ixx="1" ixy="0.0" ixz="0.0" iyy="1" iyz="0.0" izz="1"/>
    </inertial>
  </link>
  <joint name="1_pcm_joint_1" type="fixed">
    <parent link="base_footprint"/>
    <child link="1_pcm_link_1"/>
    <origin rpy="0 0 0" xyz="0 0 0.15"/>
  </joint>
  <gazebo reference="1_pcm_link_1">
    <material>Gazebo/Blue</material>
    <selfCollide>false</selfCollide>
  </gazebo>
  <link name="1_jm_link2_0">
    <visual>
      <geometry>
        <sphere radius="0.2"/>
      </geometry>
      <material name="Grey2">
          </material>
    </visual>
    <collision>
      <geometry>
        <sphere radius="0.2"/>
      </geometry>
    </collision>
    <inertial>
      <mass value="1"/>
      <inertia ixx="1" ixy="0.0" ixz="0.0" iyy="1" iyz="0.0" izz="1"/>
    </inertial>
  </link>
  <joint name="1_jm_joint2_0" type="fixed">
    <parent link="base_footprint"/>
    <child link="1_jm_link2_0"/>
    <origin rpy="0 0 0" xyz="0.0 0 0"/>
    <axis xyz="0 0 1"/>
    <limit effort="100" lower="-1.57079632679" upper="1.57079632679" velocity="100"/>
  </joint>
  <gazebo reference="1_jm_link2_0">
    <material>Gazebo/Grey</material>
    <selfCollide>false</selfCollide>
  </gazebo>
  <link name="1_jm_link_1">
    <visual>
      <geometry>
        <box size="0.1 0.4 0.3"/>
      </geometry>
      <material name="Grey2">
        </material>
    </visual>
    <collision>
      <geometry>
        <box size="0.1 0.4 0.3"/>
      </geometry>
    </collision>
    <inertial>
      <mass value="1"/>
      <inertia ixx="1" ixy="0.0" ixz="0.0" iyy="1" iyz="0.0" izz="1"/>
    </inertial>
  </link>
  <joint name="1_jm_joint_1" type="continuous">
    <parent link="1_jm_link2_0"/>
    <child link="1_jm_link_1"/>
    <axis xyz="1 0 0"/>
    <origin rpy="0 -0.0 0" xyz="-0.25 0 0"/>
  </joint>
  <gazebo reference="1_jm_link_1">
    <material>Gazebo/Grey</material>
    <selfCollide>false</selfCollide>
  </gazebo>
  <link name="1_jm_link_2">
    <visual>
      <geometry>
        <box size="0.1 0.4 0.3"/>
      </geometry>
      <material name="Grey2">
        </material>
    </visual>
    <collision>
      <geometry>
        <box size="0.1 0.4 0.3"/>
      </geometry>
    </collision>
    <inertial>
      <mass value="1"/>
      <inertia ixx="1" ixy="0.0" ixz="0.0" iyy="1" iyz="0.0" izz="1"/>
    </inertial>
  </link>
  <joint name="1_jm_joint_2" type="continuous">
    <parent link="1_jm_link2_0"/>
    <child link="1_jm_link_2"/>
    <axis xyz="1 0 0"/>
    <origin rpy="0 -0.0 0" xyz="0.25 0 0"/>
  </joint>
  <gazebo reference="1_jm_link_2">
    <material>Gazebo/Grey</material>
    <selfCollide>false</selfCollide>
  </gazebo>
  <gazebo>
    <plugin filename="libgazebo_ros_diff_drive.so" name="differential_drive_controller">
      <alwaysOn>true</alwaysOn>
      <updateRate/>
      <leftJoint>1_jm_joint_1</leftJoint>
      <rightJoint>1_jm_joint_2</rightJoint>
      <wheelSeparation>0.6</wheelSeparation>
      <wheelDiameter>0.6</wheelDiameter>
      <torque>20</torque>
      <commandTopic>mrs/cmd_vel</commandTopic>
      <odometryTopic>odom</odometryTopic>
      <odometryFrame>odom</odometryFrame>
      <robotBaseFrame>base_footprint</robotBaseFrame>
    </plugin>
  </gazebo>
  <link name="1_sm_wheel_link_1">
    <visual>
      <geometry>
        <cylinder length="0.2" radius="0.35"/>
      </geometry>
      <material name="Black">
        </material>
    </visual>
    <collision>
      <geometry>
        <cylinder length="0.2" radius="0.35"/>
      </geometry>
    </collision>
    <inertial>
      <mass value="1"/>
      <inertia ixx="1" ixy="0.0" ixz="0.0" iyy="1" iyz="0.0" izz="1"/>
    </inertial>
  </link>
  <joint name="1_sm_wheel_joint_1" type="fixed">
    <parent link="1_jm_link_1"/>
    <child link="1_sm_wheel_link_1"/>
    <origin rpy=" 0 1.57079632679 0" xyz="-0.15 0 0"/>
  </joint>
  <gazebo reference="1_sm_wheel_link_1">
    <material>Gazebo/White</material>
    <selfCollide>false</selfCollide>
  </gazebo>
  <link name="1_sm_wheel_link_2">
    <visual>
      <geometry>
        <cylinder length="0.2" radius="0.35"/>
      </geometry>
      <material name="Black">
        </material>
    </visual>
    <collision>
      <geometry>
        <cylinder length="0.2" radius="0.35"/>
      </geometry>
    </collision>
    <inertial>
      <mass value="1"/>
      <inertia ixx="1" ixy="0.0" ixz="0.0" iyy="1" iyz="0.0" izz="1"/>
    </inertial>
  </link>
  <joint name="1_sm_wheel_joint_2" type="fixed">
    <parent link="1_jm_link_2"/>
    <child link="1_sm_wheel_link_2"/>
    <origin rpy=" 0 1.57079632679 0" xyz="0.15 0 0"/>
  </joint>
  <gazebo reference="1_sm_wheel_link_2">
    <material>Gazebo/White</material>
    <selfCollide>false</selfCollide>
  </gazebo>
  <gazebo>
    <!--
    <plugin name="gazebo_ros_control" filename="libgazebo_ros_control.so">
      <robotNamespace>/mrs</robotNamespace>
    </plugin>
-->
  </gazebo>
</robot>
