<?xml version="1.0"?>
<robot xmlns:xacro="http://www.ros.org/wiki/xacro">

		<!-- Constants for robot -->
	<xacro:include filename="$(find mrs_description)/urdf/common_mrs.xacro" />
  <!-- simplified box collision geometry for base -->

  <property name="mass" value="22.0"/>
  
   <!-- Size of square 'camera' box -->
  <xacro:property name="camera_size" value="0.05" /> 
 
	<xacro:macro name="Camera" params="parent prefix x y z instance">
    <joint name="${instance}_${prefix}_camera_joint" type="fixed">
      <axis xyz="1 0 0" />
      <parent link="${parent}" />
      <child link="${instance}_${prefix}_camera_link" />
      <origin rpy="0 0 0" xyz="${x} ${y} ${z}" />
    </joint>
    <link name="${instance}_${prefix}_camera_link">
      <visual>
        <geometry>
          	<box size="${camera_size} ${camera_size} ${camera_size}"/>
        </geometry>
        <origin rpy="0 0 0 " xyz="0 0 0" />
        <material name="Red"/>
      </visual>
      <collision>
        <origin rpy="0 0 0 " xyz="0 0 0" />
        <geometry>
          	<box size="${camera_size} ${camera_size} ${camera_size}"/>
        </geometry>
      </collision>    
      <inertial>
        <mass value="1e-5" />
        <origin xyz="0 0 0" rpy="0 0 0"/>
        <inertia ixx="1e-6" ixy="0" ixz="0" iyy="1e-6" iyz="0" izz="1e-6" />
      </inertial>
    </link>
    <gazebo reference="${instance}_${prefix}_camera_link">
      <mu1>0.2</mu1>
      <mu2>0.2</mu2>
      <material>Gazebo/Red</material>
      
      <sensor type="camera" name="${instance}_${prefix}_camera">
        <always_on>true</always_on>
        <update_rate>30.0</update_rate>
        <camera name="${instance}_${prefix}_camera">
          <horizontal_fov>1.3962634</horizontal_fov>
          <image>
            <width>800</width>
            <height>800</height>
            <format>R8G8B8</format>
          </image>
          <clip>
            <near>0.02</near>
            <far>300</far>
          </clip>
        </camera>
        <plugin name="camera_controller" filename="libgazebo_ros_camera.so">
<!--
          <alwaysOn>true</alwaysOn>
          <updateRate>30.0</updateRate>
-->
          <cameraName>mrs/${instance}_${prefix}_camera</cameraName>
          <imageTopicName>image_raw</imageTopicName>
          <cameraInfoTopicName>camera_info</cameraInfoTopicName>
          <frameName>camera_link</frameName>
          <hackBaseline>0.07</hackBaseline>
          <distortionK1>0.0</distortionK1>
          <distortionK2>0.0</distortionK2>
          <distortionK3>0.0</distortionK3>
          <distortionT1>0.0</distortionT1>
          <distortionT2>0.0</distortionT2>
        </plugin>
      </sensor>
    </gazebo>

	</xacro:macro>
  
  <xacro:macro name="IMU" params="parent prefix x y z">
    <joint name="${prefix}_imu_joint" type="fixed">
      <axis xyz="1 0 0" />
      <parent link="${parent}" />
      <child link="${prefix}_imu_link" />
      <origin rpy="0 0 0" xyz="${x} ${y} ${z}" />
    </joint>
    <link name="${prefix}_imu_link">
      <visual>
        <geometry>
          	<box size="0.001 0.001 0.001"/>
        </geometry>
        <origin rpy="0 0 0 " xyz="0 0 0" />
        <material name="Red"/>
      </visual>
      <collision>
        <origin rpy="0 0 0 " xyz="0 0 0" />
        <geometry>
          	<box size="0.001 0.001 0.001"/>
        </geometry>
      </collision>    
      <inertial>
        <mass value="1e-5" />
        <origin xyz="0 0 0" rpy="0 0 0"/>
        <inertia ixx="1e-6" ixy="0" ixz="0" iyy="1e-6" iyz="0" izz="1e-6" />
      </inertial>
    </link>
    <gazebo>
<!--
      <sensor name="Vilma_IMU" type="imu">
        <pose>0 0 0 0 0 0</pose>
        <imu>
          <topic>__default_topic__</topic>
        </imu>
        <always_on>1</always_on>
        <update_rate>30</update_rate>
      </sensor>
-->
      <plugin filename="libgazebo_ros_imu.so" name="imu_en_ros">
        <bodyName>${prefix}_imu_link</bodyName>
        <robotNamespace>mrs</robotNamespace>
        <topicName>${prefix}_IMU</topicName>
      </plugin>
    </gazebo>
      
  </xacro:macro>  
  
	<xacro:macro name="Laser" params="parent prefix x y z instance">
    <joint name="${instance}_${prefix}_laser_joint" type="fixed">
      <axis xyz="1 0 0" />
      <parent link="${parent}" />
      <child link="${instance}_${prefix}_laser_link" />
      <origin rpy="0 0 0" xyz="${x} ${y} ${z}" />
    </joint>
    <link name="${instance}_${prefix}_laser_link">
      <visual>
        <geometry>
          	<box size="${camera_size} ${camera_size} ${camera_size}"/>
        </geometry>
        <origin rpy="0 0 0 " xyz="0 0 0" />
        <material name="Red"/>
      </visual>
      <collision>
        <origin rpy="0 0 0 " xyz="0 0 0" />
        <geometry>
          	<mesh filename="package://mrs_description/meshes/hokuyo.dae"/>
        </geometry>
      </collision>    
      <inertial>
        <mass value="1e-5" />
        <origin xyz="0 0 0" rpy="0 0 0"/>
        <inertia ixx="1e-6" ixy="0" ixz="0" iyy="1e-6" iyz="0" izz="1e-6" />
      </inertial>
    </link>
    <gazebo reference="${instance}_${prefix}_laser_link">
      <sensor type="gpu_ray" name="${instance}_${prefix}_lasersensor">
        <pose>0 0 0 0 0 0</pose>
        <visualize>false</visualize>
        <update_rate>40</update_rate>
        <ray>
          <scan>
            <horizontal>
              <samples>720</samples>
              <resolution>1</resolution>
              <min_angle>-1.570796</min_angle>
              <max_angle>1.570796</max_angle>
            </horizontal>
          </scan>
          <range>
            <min>0.10</min>
            <max>30.0</max>
            <resolution>0.01</resolution>
          </range>
        </ray>
        <plugin name="gazebo_ros_head_hokuyo_controller" filename="libgazebo_ros_gpu_laser.so">
          <topicName>/mrs/${instance}_${prefix}_lasersensor</topicName>
          <frameName>${instance}_${prefix}_laser_link</frameName>
        </plugin>
      </sensor>
    </gazebo>
	</xacro:macro>
  
  
  
	<xacro:macro name="SMRadprobe" params="parent prefix reflect instance">
		<joint name="${instance}_${prefix}_SMRadprobe_joint" type="fixed">
			<parent link="${parent}" />
			<child link="${instance}_${prefix}_rad_pole" />
			<origin rpy="0 ${-pi/2} 0" xyz="-0.1 0 0" />
		</joint>
		<link name="${instance}_${prefix}_rad_pole">
			<visual>
				<geometry>
					<cylinder length="0.2" radius=".03" />
				</geometry>
				<origin rpy="0 0 0 " xyz="0 0 0" />
				<material name="Gray">
					<color rgba=".7 .7 .7 1" />
				</material>
			</visual>
		</link>
		<joint name="${instance}_${prefix}_rad_joint" type="fixed">
			<axis xyz="0 0 1" />
			<origin rpy="0 0 0" xyz="0 0 0.1" />
			<parent link="${instance}_${prefix}_rad_pole" />
			<child link="${instance}_${prefix}_rad" />
		</joint>
		<link name="${instance}_${prefix}_rad">
			<visual>
				<origin rpy="0.0 0 0" xyz="0 0 0" />
				<geometry>
					<cylinder length="0.05" radius=".05" />
				</geometry>
								<material name="Black"/>
			</visual>
		</link>
    <gazebo reference="${instance}_${prefix}_rad_pole">
      <material>Gazebo/Red</material>
      <selfCollide>false</selfCollide>
    </gazebo>
    <gazebo reference="${instance}_${prefix}_rad">
      <material>Gazebo/Black</material>
      <selfCollide>false</selfCollide>
    </gazebo>
	</xacro:macro>
	
	
	<xacro:macro name="SMHand" params="parent prefix reflect instance">
		<joint name="${instance}_${prefix}_SMHand_joint" type="fixed">
			<parent link="${parent}" />
			<child link="${instance}_${prefix}_gripper_pole" />
			<origin rpy="0 0 1.57075" xyz="0 0 0.2" />
		</joint>
		<link name="${instance}_${prefix}_gripper_pole">
			<visual>
				<geometry>
					<cylinder length="0.3" radius=".02" />
				</geometry>
				<origin rpy="0 0 0 " xyz="0 0 0" />
				<material name="Gray">
					<color rgba=".7 .7 .7 1" />
				</material>
			</visual>
		</link>
		<joint name="${instance}_${prefix}_left_gripper_joint" type="revolute">
			<axis xyz="0 0 1" />
			<limit effort="1000.0" lower="0.0" upper="0.548" velocity="0.5" />
			<origin rpy="0 0 0" xyz="0 0.01 0.2" />
			<parent link="${instance}_${prefix}_gripper_pole" />
			<child link="${instance}_${prefix}_left_gripper" />
		</joint>
		<link name="${instance}_${prefix}_left_gripper">
			<visual>
				<origin rpy="0.0 0 0" xyz="0 0 0" />
				<geometry>
					<mesh filename="package://pr2_description/meshes/gripper_v0/l_finger.dae" />
				</geometry>
			</visual>
		</link>
		<joint name="${instance}_${prefix}_left_tip_joint" type="fixed">
			<parent link="${instance}_${prefix}_left_gripper" />
			<child link="${instance}_${prefix}_left_tip" />
		</joint>
		<link name="${instance}_${prefix}_left_tip">
			<visual>
				<origin rpy="0.0 0 0" xyz="0.09137 0.00495 0" />
				<geometry>
					<mesh
						filename="package://pr2_description/meshes/gripper_v0/l_finger_tip.dae" />
				</geometry>
			</visual>
		</link>
		<joint name="${instance}_${prefix}_right_gripper_joint" type="revolute">
			<axis xyz="0 0 -1" />
			<limit effort="1000.0" lower="0.0" upper="0.548" velocity="0.5" />
			<origin rpy="0 0 0" xyz="0 -0.01 0.2" />
			<parent link="${instance}_${prefix}_gripper_pole" />
			<child link="${instance}_${prefix}_right_gripper" />
		</joint>
		<link name="${instance}_${prefix}_right_gripper">
			<visual>
				<origin rpy="-3.1415 0 0" xyz="0 0 0" />
				<geometry>
					<mesh filename="package://pr2_description/meshes/gripper_v0/l_finger.dae" />
				</geometry>
			</visual>
		</link>
		<joint name="${instance}_${prefix}_right_tip_joint" type="fixed">
			<parent link="${instance}_${prefix}_right_gripper" />
			<child link="${instance}_${prefix}_right_tip" />
		</joint>
		<link name="${instance}_${prefix}_right_tip">
			<visual>
				<origin rpy="-3.1415 0 0" xyz="0.09137 0.00495 0" />
				<geometry>
					<mesh
						filename="package://pr2_description/meshes/gripper_v0/l_finger_tip.dae" />
				</geometry>
			</visual>
		</link>
    <gazebo reference="${instance}_${prefix}_gripper_pole">
      <material>Gazebo/Grey</material>
      <selfCollide>false</selfCollide>
    </gazebo>
    <gazebo reference="${instance}_${prefix}_left_gripper">
      <material>Gazebo/Grey</material>
      <selfCollide>false</selfCollide>
    </gazebo>
    <gazebo reference="${instance}_${prefix}_left_tip">
      <material>Gazebo/Grey</material>
      <selfCollide>false</selfCollide>
    </gazebo>
    <gazebo reference="${instance}_${prefix}_right_gripper">
      <material>Gazebo/Grey</material>
      <selfCollide>false</selfCollide>
    </gazebo>
	</xacro:macro>
	
</robot>
